<?xml version="1.0" ?>
<!-- =================================================================================== -->
<!-- |    This document was autogenerated by xacro from urdf/aiear.xacro               | -->
<!-- |    EDITING THIS FILE BY HAND IS NOT RECOMMENDED                                 | -->
<!-- =================================================================================== -->
<!--
  AIEAR – Autonomous Indoor Emergency Aid Robot
  URDF/Xacro for ROS 2 Jazzy + Gazebo Harmonic (gz-sim 8)

  Design document values
  ──────────────────────
  Chassis : 350 × 280 × 120 mm,  3 kg
  Wheels  : JGB37-520B  ø112 mm (r=56 mm), width 40 mm
  Wheelbase (left-right centre-to-centre) : 240 mm
  Front wheel pair  : x = +100 mm from chassis centre
  Rear  wheel pair  : x = −100 mm from chassis centre
  Caster (passive)  : ø50 mm sphere, front underside
  RPLiDAR A1        : centre of chassis, top height from ground = 200 mm
  IMX500 camera     : front-top edge of chassis, tilted 20 ° downward

  Coordinate frame (ROS REP-103)
  ───────────────────────────────
  base_footprint    – ground-projected centre  (z = 0)
  base_link         – chassis centre
    z = wheel_radius + chassis_height/2 = 0.056 + 0.06 = 0.116 m above ground
-->
<robot name="aiear">
  <!-- ================================================================
       GAZEBO PLUGINS
       ================================================================ -->
  <!-- ── 1. Differential Drive ─────────────────────────────────── -->
  <!--
    Left side  : front_left  + rear_left  joints
    Right side : front_right + rear_right joints
    wheel_separation = wheelbase = 0.24 m
    wheel_radius     = 0.056 m
  -->
  <gazebo>
    <plugin filename="gz-sim-diff-drive-system" name="gz::sim::systems::DiffDrive">
      <left_joint>front_left_wheel_joint</left_joint>
      <left_joint>rear_left_wheel_joint</left_joint>
      <right_joint>front_right_wheel_joint</right_joint>
      <right_joint>rear_right_wheel_joint</right_joint>
      <wheel_separation>wheelbase</wheel_separation>
      <wheel_radius>wheel_radius</wheel_radius>
      <odom_publish_frequency>20</odom_publish_frequency>
      <!-- Global Gz topics (leading / → no model-namespace prefix) -->
      <topic>/cmd_vel</topic>
      <odom_topic>/odom</odom_topic>
      <tf_topic>/tf</tf_topic>
      <frame_id>odom</frame_id>
      <child_frame_id>base_footprint</child_frame_id>
      <min_acceleration>-5</min_acceleration>
      <max_acceleration>10</max_acceleration>
    </plugin>
  </gazebo>
  <!-- ── 2. Joint State Publisher ──────────────────────────────── -->
  <gazebo>
    <plugin filename="gz-sim-joint-state-publisher-system" name="gz::sim::systems::JointStatePublisher">
      <joint_name>front_left_wheel_joint</joint_name>
      <joint_name>front_right_wheel_joint</joint_name>
      <joint_name>rear_left_wheel_joint</joint_name>
      <joint_name>rear_right_wheel_joint</joint_name>
      <topic>/joint_states</topic>
      <update_rate>50</update_rate>
    </plugin>
  </gazebo>
  <!-- ── 3. RPLiDAR A1 GPU LiDAR Sensor ────────────────────────── -->
  <!--
    360° scan, 5.5 Hz, range 0.15–12 m, 360 samples
  -->
  <gazebo reference="lidar_link">
    <sensor name="rplidar_a1" type="lidar">
      <update_rate>5.5</update_rate>
      <topic>/scan</topic>
      <gz_frame_id>lidar_link</gz_frame_id>
      <lidar>
        <scan>
          <horizontal>
            <samples>360</samples>
            <resolution>1</resolution>
            <min_angle>-3.14159265358979</min_angle>
            <max_angle>3.14159265358979</max_angle>
          </horizontal>
          <vertical>
            <samples>1</samples>
            <resolution>1</resolution>
            <min_angle>0</min_angle>
            <max_angle>0</max_angle>
          </vertical>
        </scan>
        <range>
          <min>0.15</min>
          <max>12.0</max>
          <resolution>0.01</resolution>
        </range>
        <noise>
          <type>gaussian</type>
          <mean>0.0</mean>
          <stddev>0.01</stddev>
        </noise>
      </lidar>
      <always_on>true</always_on>
      <visualize>true</visualize>
    </sensor>
  </gazebo>
  <!-- ── 4. IMX500 Camera Sensor ───────────────────────────────── -->
  <!--
    1080p, 30 fps, 60° horizontal FOV
  -->
  <gazebo reference="camera_link">
    <sensor name="imx500_camera" type="camera">
      <update_rate>30</update_rate>
      <topic>/camera/image_raw</topic>
      <gz_frame_id>camera_optical_link</gz_frame_id>
      <camera>
        <horizontal_fov>cam_fov</horizontal_fov>
        <image>
          <width>1920</width>
          <height>1080</height>
          <format>R8G8B8</format>
        </image>
        <clip>
          <near>0.1</near>
          <far>100.0</far>
        </clip>
        <noise>
          <type>gaussian</type>
          <mean>0.0</mean>
          <stddev>0.007</stddev>
        </noise>
      </camera>
      <always_on>true</always_on>
      <visualize>true</visualize>
    </sensor>
  </gazebo>
  <!-- ================================================================
       PROPERTIES
       ================================================================ -->
  <!-- ================================================================
       INERTIA MACROS
       ================================================================ -->
  <!-- ================================================================
       LINKS
       ================================================================ -->
  <!-- base_footprint: ground-projected reference link (REP-105) -->
  <link name="base_footprint"/>
  <joint name="base_footprint_joint" type="fixed">
    <parent link="base_footprint"/>
    <child link="base_link"/>
    <origin rpy="0 0 0" xyz="0 0 0.11599999999999999"/>
  </joint>
  <!-- ── Chassis (base_link) ─────────────────────────────────────── -->
  <link name="base_link">
    <visual>
      <origin rpy="0 0 0" xyz="0 0 0"/>
      <geometry>
        <box size="0.35 0.28 0.12"/>
      </geometry>
      <material name="aiear_blue">
        <color rgba="0.80 1.0 0.60 1.0"/>
      </material>
    </visual>
    <collision>
      <origin rpy="0 0 0" xyz="0 0 0"/>
      <geometry>
        <box size="0.35 0.28 0.12"/>
      </geometry>
    </collision>
    <inertial>
      <mass value="3.0"/>
      <origin rpy="0 0 0" xyz="0 0 0"/>
      <inertia ixx="0.023200000000000002" ixy="0.0" ixz="0.0" iyy="0.034225" iyz="0.0" izz="0.050225"/>
    </inertial>
  </link>
  <gazebo reference="base_link">
    <material>Gazebo/Blue</material>
  </gazebo>
  <link name="front_left_wheel_link">
    <visual>
      <!-- Rotate cylinder from Z-axis to Y-axis for correct wheel orientation -->
      <origin rpy="1.5707963267948966 0 0" xyz="0 0 0"/>
      <geometry>
        <cylinder length="0.04" radius="0.056"/>
      </geometry>
      <material name="dark_grey">
        <color rgba="0.2 0.2 0.2 1.0"/>
      </material>
    </visual>
    <collision>
      <origin rpy="1.5707963267948966 0 0" xyz="0 0 0"/>
      <geometry>
        <cylinder length="0.04" radius="0.056"/>
      </geometry>
    </collision>
    <inertial>
      <mass value="0.3"/>
      <origin rpy="0 0 0" xyz="0 0 0"/>
      <inertia ixx="0.0002752" ixy="0.0" ixz="0.0" iyy="0.0004704" iyz="0.0" izz="0.0002752"/>
    </inertial>
  </link>
  <joint name="front_left_wheel_joint" type="continuous">
    <parent link="base_link"/>
    <child link="front_left_wheel_link"/>
    <origin rpy="0 0 0" xyz="0.1 0.12 -0.06"/>
    <axis xyz="0 1 0"/>
    <dynamics damping="0.05" friction="0.05"/>
  </joint>
  <!-- Gazebo wheel surface properties -->
  <gazebo reference="front_left_wheel_link">
    <material>Gazebo/DarkGrey</material>
    <surface>
      <friction>
        <ode>
          <mu>0.8</mu>
          <mu2>0.8</mu2>
        </ode>
      </friction>
    </surface>
  </gazebo>
  <link name="front_right_wheel_link">
    <visual>
      <!-- Rotate cylinder from Z-axis to Y-axis for correct wheel orientation -->
      <origin rpy="1.5707963267948966 0 0" xyz="0 0 0"/>
      <geometry>
        <cylinder length="0.04" radius="0.056"/>
      </geometry>
      <material name="dark_grey">
        <color rgba="0.2 0.2 0.2 1.0"/>
      </material>
    </visual>
    <collision>
      <origin rpy="1.5707963267948966 0 0" xyz="0 0 0"/>
      <geometry>
        <cylinder length="0.04" radius="0.056"/>
      </geometry>
    </collision>
    <inertial>
      <mass value="0.3"/>
      <origin rpy="0 0 0" xyz="0 0 0"/>
      <inertia ixx="0.0002752" ixy="0.0" ixz="0.0" iyy="0.0004704" iyz="0.0" izz="0.0002752"/>
    </inertial>
  </link>
  <joint name="front_right_wheel_joint" type="continuous">
    <parent link="base_link"/>
    <child link="front_right_wheel_link"/>
    <origin rpy="0 0 0" xyz="0.1 -0.12 -0.06"/>
    <axis xyz="0 1 0"/>
    <dynamics damping="0.05" friction="0.05"/>
  </joint>
  <!-- Gazebo wheel surface properties -->
  <gazebo reference="front_right_wheel_link">
    <material>Gazebo/DarkGrey</material>
    <surface>
      <friction>
        <ode>
          <mu>0.8</mu>
          <mu2>0.8</mu2>
        </ode>
      </friction>
    </surface>
  </gazebo>
  <link name="rear_left_wheel_link">
    <visual>
      <!-- Rotate cylinder from Z-axis to Y-axis for correct wheel orientation -->
      <origin rpy="1.5707963267948966 0 0" xyz="0 0 0"/>
      <geometry>
        <cylinder length="0.04" radius="0.056"/>
      </geometry>
      <material name="dark_grey">
        <color rgba="0.2 0.2 0.2 1.0"/>
      </material>
    </visual>
    <collision>
      <origin rpy="1.5707963267948966 0 0" xyz="0 0 0"/>
      <geometry>
        <cylinder length="0.04" radius="0.056"/>
      </geometry>
    </collision>
    <inertial>
      <mass value="0.3"/>
      <origin rpy="0 0 0" xyz="0 0 0"/>
      <inertia ixx="0.0002752" ixy="0.0" ixz="0.0" iyy="0.0004704" iyz="0.0" izz="0.0002752"/>
    </inertial>
  </link>
  <joint name="rear_left_wheel_joint" type="continuous">
    <parent link="base_link"/>
    <child link="rear_left_wheel_link"/>
    <origin rpy="0 0 0" xyz="-0.1 0.12 -0.06"/>
    <axis xyz="0 1 0"/>
    <dynamics damping="0.05" friction="0.05"/>
  </joint>
  <!-- Gazebo wheel surface properties -->
  <gazebo reference="rear_left_wheel_link">
    <material>Gazebo/DarkGrey</material>
    <surface>
      <friction>
        <ode>
          <mu>0.8</mu>
          <mu2>0.8</mu2>
        </ode>
      </friction>
    </surface>
  </gazebo>
  <link name="rear_right_wheel_link">
    <visual>
      <!-- Rotate cylinder from Z-axis to Y-axis for correct wheel orientation -->
      <origin rpy="1.5707963267948966 0 0" xyz="0 0 0"/>
      <geometry>
        <cylinder length="0.04" radius="0.056"/>
      </geometry>
      <material name="dark_grey">
        <color rgba="0.2 0.2 0.2 1.0"/>
      </material>
    </visual>
    <collision>
      <origin rpy="1.5707963267948966 0 0" xyz="0 0 0"/>
      <geometry>
        <cylinder length="0.04" radius="0.056"/>
      </geometry>
    </collision>
    <inertial>
      <mass value="0.3"/>
      <origin rpy="0 0 0" xyz="0 0 0"/>
      <inertia ixx="0.0002752" ixy="0.0" ixz="0.0" iyy="0.0004704" iyz="0.0" izz="0.0002752"/>
    </inertial>
  </link>
  <joint name="rear_right_wheel_joint" type="continuous">
    <parent link="base_link"/>
    <child link="rear_right_wheel_link"/>
    <origin rpy="0 0 0" xyz="-0.1 -0.12 -0.06"/>
    <axis xyz="0 1 0"/>
    <dynamics damping="0.05" friction="0.05"/>
  </joint>
  <!-- Gazebo wheel surface properties -->
  <gazebo reference="rear_right_wheel_link">
    <material>Gazebo/DarkGrey</material>
    <surface>
      <friction>
        <ode>
          <mu>0.8</mu>
          <mu2>0.8</mu2>
        </ode>
      </friction>
    </surface>
  </gazebo>
  <!-- ── Passive Caster Wheel (front underside) ────────────────── -->
  <link name="caster_wheel_link">
    <visual>
      <origin rpy="0 0 0" xyz="0 0 0"/>
      <geometry>
        <sphere radius="0.025"/>
      </geometry>
      <material name="light_grey">
        <color rgba="0.70 0.70 0.70 1.0"/>
      </material>
    </visual>
    <collision>
      <origin rpy="0 0 0" xyz="0 0 0"/>
      <geometry>
        <sphere radius="0.025"/>
      </geometry>
    </collision>
    <inertial>
      <mass value="0.05"/>
      <origin rpy="0 0 0" xyz="0 0 0"/>
      <inertia ixx="1.2500000000000002e-05" ixy="0.0" ixz="0.0" iyy="1.2500000000000002e-05" iyz="0.0" izz="1.2500000000000002e-05"/>
    </inertial>
  </link>
  <joint name="caster_wheel_joint" type="fixed">
    <parent link="base_link"/>
    <child link="caster_wheel_link"/>
    <origin rpy="0 0 0" xyz="0.13 0 -0.091"/>
  </joint>
  <!-- Zero friction so the caster slides freely -->
  <gazebo reference="caster_wheel_link">
    <material>Gazebo/Grey</material>
    <surface>
      <friction>
        <ode>
          <mu1>0.0</mu1>
          <mu2>0.0</mu2>
        </ode>
      </friction>
    </surface>
  </gazebo>
  <!-- ── LiDAR Riser Post ──────────────────────────────────────── -->
  <link name="lidar_riser_link">
    <visual>
      <origin rpy="0 0 0" xyz="0 0 0"/>
      <geometry>
        <cylinder length="0.004000000000000021" radius="0.008"/>
      </geometry>
      <material name="aluminium">
        <color rgba="0.75 0.75 0.75 1.0"/>
      </material>
    </visual>
    <collision>
      <origin rpy="0 0 0" xyz="0 0 0"/>
      <geometry>
        <cylinder length="0.004000000000000021" radius="0.008"/>
      </geometry>
    </collision>
    <inertial>
      <mass value="0.05"/>
      <origin rpy="0 0 0" xyz="0 0 0"/>
      <inertia ixx="8.666666666666674e-07" ixy="0.0" ixz="0.0" iyy="8.666666666666674e-07" iyz="0.0" izz="1.6000000000000001e-06"/>
    </inertial>
  </link>
  <!-- Riser base sits at chassis top; riser joint at chassis-top level -->
  <joint name="lidar_riser_joint" type="fixed">
    <parent link="base_link"/>
    <child link="lidar_riser_link"/>
    <!-- Centre the riser between chassis top and lidar bottom -->
    <origin rpy="0 0 0" xyz="0 0 0.062000000000000006"/>
  </joint>
  <!-- ── RPLiDAR A1 Sensor Link ─────────────────────────────────── -->
  <!--
    Total height from ground = 200 mm
    lidar_z from base_link  = 0.200 − 0.116 = 0.084 m
  -->
  <link name="lidar_link">
    <visual>
      <origin rpy="0 0 0" xyz="0 0 0"/>
      <geometry>
        <cylinder length="0.04" radius="0.038"/>
      </geometry>
      <material name="lidar_black">
        <color rgba="0.10 0.10 0.10 1.0"/>
      </material>
    </visual>
    <collision>
      <origin rpy="0 0 0" xyz="0 0 0"/>
      <geometry>
        <cylinder length="0.04" radius="0.038"/>
      </geometry>
    </collision>
    <inertial>
      <mass value="0.17"/>
      <origin rpy="0 0 0" xyz="0 0 0"/>
      <inertia ixx="8.403666666666666e-05" ixy="0.0" ixz="0.0" iyy="8.403666666666666e-05" iyz="0.0" izz="0.00012274"/>
    </inertial>
  </link>
  <joint name="lidar_joint" type="fixed">
    <parent link="base_link"/>
    <child link="lidar_link"/>
    <origin rpy="0 0 0" xyz="0 0 0.08400000000000002"/>
  </joint>
  <!-- ── IMX500 Camera Link ─────────────────────────────────────── -->
  <link name="camera_link">
    <visual>
      <!-- Small rectangular module: 25 mm × 90 mm × 25 mm -->
      <origin rpy="0 0 0" xyz="0 0 0"/>
      <geometry>
        <box size="0.025 0.090 0.025"/>
      </geometry>
      <material name="cam_black">
        <color rgba="0.05 0.05 0.05 1.0"/>
      </material>
    </visual>
    <collision>
      <origin rpy="0 0 0" xyz="0 0 0"/>
      <geometry>
        <box size="0.025 0.090 0.025"/>
      </geometry>
    </collision>
    <inertial>
      <mass value="0.05"/>
      <origin rpy="0 0 0" xyz="0 0 0"/>
      <inertia ixx="3.6354166666666665e-05" ixy="0.0" ixz="0.0" iyy="5.208333333333335e-06" iyz="0.0" izz="3.6354166666666665e-05"/>
    </inertial>
  </link>
  <!-- Camera optical frame (Z forward in camera convention) -->
  <link name="camera_optical_link"/>
  <joint name="camera_joint" type="fixed">
    <parent link="base_link"/>
    <child link="camera_link"/>
    <!-- Front-top edge; pitch down 20° -->
    <origin rpy="0 -0.3490658503988659 0" xyz="0.175 0 0.06"/>
  </joint>
  <joint name="camera_optical_joint" type="fixed">
    <parent link="camera_link"/>
    <child link="camera_optical_link"/>
    <!-- ROS camera convention: rotate so Z points forward, Y points down -->
    <origin rpy="-1.5707963267948966 0 -1.5707963267948966" xyz="0 0 0"/>
  </joint>
</robot>
