<?xml version="1.0" ?>
<!-- =================================================================================== -->
<!-- |    This document was autogenerated by xacro from /home/bc/Documents/Projects/fyp/ROS/aiear_ws/src/aiear_robot/model/robot.xacro | -->
<!-- |    EDITING THIS FILE BY HAND IS NOT RECOMMENDED                                 | -->
<!-- =================================================================================== -->
<robot name="aiear_robot">
  <!-- 20mm fillet -->
  <!-- ================================================================
       INCLUDES
       ================================================================ -->
  <!-- <xacro:include filename="$(find aiear_robot)/model/robot.gazebo" /> -->
  <!-- <xacro:if value="$(arg use_ros2_control)">
        <xacro:include filename="$(find aiear_robot)/model/ros2_control.xacro" />
    </xacro:if> -->
  <!-- ================================================================
       MACROS
       ================================================================ -->
  <ros2_control name="AiearHardwareInterface" type="system">
    <hardware>
      <!-- <xacro:if value="$(arg is_sim)"> -->
      <!-- <plugin>gz_ros2_control/GazeboSimSystem</plugin> -->
      <plugin>mock_components/GenericSystem</plugin>
      <!-- </xacro:if> -->
      <!-- <xacro:unless value="$(arg is_sim)"> -->
      <!-- This is where the real hardware plugin goes in the future -->
      <!-- <plugin>aiear_hardware/AiearSystemHardware</plugin> -->
      <!-- <param name="serial_port">/dev/ttyUSB0</param> -->
      <!-- </xacro:unless> -->
    </hardware>
    <!-- 2-Wheel Configuration -->
    <!-- <xacro:if value="${'$(arg wheel_count)' == '2'}"> -->
    <!-- <joint name="left_wheel_joint">
                <command_interface name="velocity">
                    <param name="min">-10</param>
                    <param name="max">10</param>
                </command_interface>
                <state_interface name="position" />
                <state_interface name="velocity" />
            </joint>
            <joint name="right_wheel_joint">
                <command_interface name="velocity">
                    <param name="min">-10</param>
                    <param name="max">10</param>
                </command_interface>
                <state_interface name="position" />
                <state_interface name="velocity" />
            </joint> -->
    <!-- </xacro:if> -->
    <!-- 4-Wheel Configuration -->
    <!-- <xacro:if value="${'$(arg wheel_count)' == '4'}"> -->
    <joint name="front_left_wheel_joint">
      <command_interface name="velocity">
        <param name="min">-10</param>
        <param name="max">10</param>
      </command_interface>
      <state_interface name="position"/>
      <state_interface name="velocity"/>
    </joint>
    <joint name="front_right_wheel_joint">
      <command_interface name="velocity">
        <param name="min">-10</param>
        <param name="max">10</param>
      </command_interface>
      <state_interface name="position"/>
      <state_interface name="velocity"/>
    </joint>
    <joint name="rear_left_wheel_joint">
      <command_interface name="velocity">
        <param name="min">-10</param>
        <param name="max">10</param>
      </command_interface>
      <state_interface name="position"/>
      <state_interface name="velocity"/>
    </joint>
    <joint name="rear_right_wheel_joint">
      <command_interface name="velocity">
        <param name="min">-10</param>
        <param name="max">10</param>
      </command_interface>
      <state_interface name="position"/>
      <state_interface name="velocity"/>
    </joint>
    <!-- </xacro:if> -->
  </ros2_control>
  <!-- Gazebo Plugin for ros2_control (only if in simulation) -->
  <!-- <xacro:if value="$(arg is_sim)">
        <gazebo>
            <plugin filename="gz_ros2_control-system" name="gz_ros2_control::GazeboSimROS2ControlPlugin">
                <parameters>$(find aiear_robot)/config/my_controllers.yaml</parameters>
            </plugin>
        </gazebo>
    </xacro:if> -->
  <!-- ================================================================
       LINKS & JOINTS
       ================================================================ -->
  <!-- base_footprint -->
  <link name="base_footprint"/>
  <joint name="base_footprint_joint" type="fixed">
    <parent link="base_footprint"/>
    <child link="base_link"/>
    <origin rpy="0 0 0" xyz="0 0 0.18"/>
  </joint>
  <!-- base_link (Chassis with fillets) -->
  <link name="base_link">
    <visual>
      <geometry>
        <box size="0.33 0.26 0.25"/>
      </geometry>
    </visual>
    <visual>
      <geometry>
        <box size="0.37 0.22 0.25"/>
      </geometry>
    </visual>
    <visual>
      <geometry>
        <box size="0.37 0.26 0.21"/>
      </geometry>
    </visual>
    <!-- Simplified for now: Top/Bottom/Side boxes + Cylinders for vertical edges -->
    <!-- Vertical Edges -->
    <visual>
      <origin xyz="0.165 0.11 0"/>
      <geometry>
        <cylinder length="0.21" radius="0.02"/>
      </geometry>
    </visual>
    <visual>
      <origin xyz="0.165 -0.11 0"/>
      <geometry>
        <cylinder length="0.21" radius="0.02"/>
      </geometry>
    </visual>
    <visual>
      <origin xyz="-0.165 0.11 0"/>
      <geometry>
        <cylinder length="0.21" radius="0.02"/>
      </geometry>
    </visual>
    <visual>
      <origin xyz="-0.165 -0.11 0"/>
      <geometry>
        <cylinder length="0.21" radius="0.02"/>
      </geometry>
    </visual>
    <!-- Horizontal Edges (X) -->
    <visual>
      <origin rpy="0 1.57 0" xyz="0 0.11 0.105"/>
      <geometry>
        <cylinder length="0.33" radius="0.02"/>
      </geometry>
    </visual>
    <visual>
      <origin rpy="0 1.57 0" xyz="0 -0.11 0.105"/>
      <geometry>
        <cylinder length="0.33" radius="0.02"/>
      </geometry>
    </visual>
    <visual>
      <origin rpy="0 1.57 0" xyz="0 0.11 -0.105"/>
      <geometry>
        <cylinder length="0.33" radius="0.02"/>
      </geometry>
    </visual>
    <visual>
      <origin rpy="0 1.57 0" xyz="0 -0.11 -0.105"/>
      <geometry>
        <cylinder length="0.33" radius="0.02"/>
      </geometry>
    </visual>
    <!-- Horizontal Edges (Y) -->
    <visual>
      <origin rpy="1.57 0 0" xyz="0.165 0 0.105"/>
      <geometry>
        <cylinder length="0.22" radius="0.02"/>
      </geometry>
    </visual>
    <visual>
      <origin rpy="1.57 0 0" xyz="0.165 0 -0.105"/>
      <geometry>
        <cylinder length="0.22" radius="0.02"/>
      </geometry>
    </visual>
    <visual>
      <origin rpy="1.57 0 0" xyz="-0.165 0 0.105"/>
      <geometry>
        <cylinder length="0.22" radius="0.02"/>
      </geometry>
    </visual>
    <visual>
      <origin rpy="1.57 0 0" xyz="-0.165 0 -0.105"/>
      <geometry>
        <cylinder length="0.22" radius="0.02"/>
      </geometry>
    </visual>
    <!-- 8 Corners (Spheres) -->
    <visual>
      <origin xyz="0.165 0.11 0.105"/>
      <geometry>
        <sphere radius="0.02"/>
      </geometry>
    </visual>
    <visual>
      <origin xyz="0.165 0.11 -0.105"/>
      <geometry>
        <sphere radius="0.02"/>
      </geometry>
    </visual>
    <visual>
      <origin xyz="0.165 -0.11 0.105"/>
      <geometry>
        <sphere radius="0.02"/>
      </geometry>
    </visual>
    <visual>
      <origin xyz="0.165 -0.11 -0.105"/>
      <geometry>
        <sphere radius="0.02"/>
      </geometry>
    </visual>
    <visual>
      <origin xyz="-0.165 0.11 0.105"/>
      <geometry>
        <sphere radius="0.02"/>
      </geometry>
    </visual>
    <visual>
      <origin xyz="-0.165 0.11 -0.105"/>
      <geometry>
        <sphere radius="0.02"/>
      </geometry>
    </visual>
    <visual>
      <origin xyz="-0.165 -0.11 0.105"/>
      <geometry>
        <sphere radius="0.02"/>
      </geometry>
    </visual>
    <visual>
      <origin xyz="-0.165 -0.11 -0.105"/>
      <geometry>
        <sphere radius="0.02"/>
      </geometry>
    </visual>
    <collision>
      <origin rpy="0 0 0" xyz="0 0 0"/>
      <geometry>
        <box size="0.37 0.26 0.25"/>
      </geometry>
    </collision>
    <inertial>
      <origin rpy="0 0 0" xyz="0 0 0"/>
      <mass value="3.0"/>
      <inertia ixx="0.032525" ixy="0.0" ixz="0.0" iyy="0.04985" iyz="0.0" izz="0.051125000000000004"/>
    </inertial>
  </link>
  <link name="left_wheel_link">
    <visual>
      <origin rpy="1.5707963267948966 0 0" xyz="0 0 0"/>
      <geometry>
        <cylinder length="0.04" radius="0.055"/>
      </geometry>
      <material name="black">
        <color rgba="0.1 0.1 0.1 1.0"/>
      </material>
    </visual>
    <collision>
      <origin rpy="1.5707963267948966 0 0" xyz="0 0 0"/>
      <geometry>
        <cylinder length="0.04" radius="0.055"/>
      </geometry>
    </collision>
    <inertial>
      <origin rpy="1.5707963267948966 0 0" xyz="0 0 0"/>
      <mass value="0.3"/>
      <inertia ixx="0.000266875" ixy="0.0" ixz="0.0" iyy="0.00045375" iyz="0.0" izz="0.000266875"/>
    </inertial>
  </link>
  <joint name="left_wheel_joint" type="continuous">
    <parent link="base_link"/>
    <child link="left_wheel_link"/>
    <origin rpy="0 0 0" xyz="0 0.12 -0.125"/>
    <axis xyz="0 1 0"/>
    <dynamics damping="0.1" friction="0.1"/>
  </joint>
  <link name="right_wheel_link">
    <visual>
      <origin rpy="1.5707963267948966 0 0" xyz="0 0 0"/>
      <geometry>
        <cylinder length="0.04" radius="0.055"/>
      </geometry>
      <material name="black">
        <color rgba="0.1 0.1 0.1 1.0"/>
      </material>
    </visual>
    <collision>
      <origin rpy="1.5707963267948966 0 0" xyz="0 0 0"/>
      <geometry>
        <cylinder length="0.04" radius="0.055"/>
      </geometry>
    </collision>
    <inertial>
      <origin rpy="1.5707963267948966 0 0" xyz="0 0 0"/>
      <mass value="0.3"/>
      <inertia ixx="0.000266875" ixy="0.0" ixz="0.0" iyy="0.00045375" iyz="0.0" izz="0.000266875"/>
    </inertial>
  </link>
  <joint name="right_wheel_joint" type="continuous">
    <parent link="base_link"/>
    <child link="right_wheel_link"/>
    <origin rpy="0 0 0" xyz="0 -0.12 -0.125"/>
    <axis xyz="0 1 0"/>
    <dynamics damping="0.1" friction="0.1"/>
  </joint>
  <link name="caster_link">
    <visual>
      <geometry>
        <sphere radius="0.04"/>
      </geometry>
      <material name="grey">
        <color rgba="0.5 0.5 0.5 1.0"/>
      </material>
    </visual>
    <collision>
      <geometry>
        <sphere radius="0.04"/>
      </geometry>
    </collision>
    <inertial>
      <origin rpy="0 0 0" xyz="0 0 0"/>
      <mass value="0.05"/>
      <inertia ixx="3.2000000000000005e-05" ixy="0.0" ixz="0.0" iyy="3.2000000000000005e-05" iyz="0.0" izz="3.2000000000000005e-05"/>
    </inertial>
  </link>
  <joint name="caster_joint" type="fixed">
    <parent link="base_link"/>
    <child link="caster_link"/>
    <origin rpy="0 0 0" xyz="0.13 0 -0.13999999999999999"/>
  </joint>
  <!-- LiDAR -->
  <link name="lidar_link">
    <visual>
      <geometry>
        <cylinder length="0.04" radius="0.038"/>
      </geometry>
      <material name="dark_grey">
        <color rgba="0.2 0.2 0.2 1.0"/>
      </material>
    </visual>
    <collision>
      <geometry>
        <cylinder length="0.04" radius="0.038"/>
      </geometry>
    </collision>
    <inertial>
      <origin rpy="0 0 0" xyz="0 0 0"/>
      <mass value="0.17"/>
      <inertia ixx="8.403666666666666e-05" ixy="0.0" ixz="0.0" iyy="8.403666666666666e-05" iyz="0.0" izz="0.00012274"/>
    </inertial>
  </link>
  <joint name="lidar_joint" type="fixed">
    <parent link="base_link"/>
    <child link="lidar_link"/>
    <origin rpy="0 0 0" xyz="0.147 0 0.145"/>
  </joint>
  <!-- Camera -->
  <link name="camera_link">
    <visual>
      <geometry>
        <box size="0.025 0.090 0.025"/>
      </geometry>
      <material name="black">
        <color rgba="0.1 0.1 0.1 1.0"/>
      </material>
    </visual>
    <collision>
      <geometry>
        <box size="0.025 0.090 0.025"/>
      </geometry>
    </collision>
    <inertial>
      <origin rpy="0 0 0" xyz="0 0 0"/>
      <mass value="0.05"/>
      <inertia ixx="3.6354166666666665e-05" ixy="0.0" ixz="0.0" iyy="5.208333333333335e-06" iyz="0.0" izz="3.6354166666666665e-05"/>
    </inertial>
  </link>
  <joint name="camera_joint" type="fixed">
    <parent link="base_link"/>
    <child link="camera_link"/>
    <origin rpy="0 0 0" xyz="0.1975 0 0"/>
  </joint>
  <link name="camera_optical_link"/>
  <joint name="camera_optical_joint" type="fixed">
    <parent link="camera_link"/>
    <child link="camera_optical_link"/>
    <origin rpy="-1.5707963267948966 0 -1.5707963267948966" xyz="0 0 0"/>
  </joint>
</robot>
